Workbook

Sheet Summary
A1: Nuveen Housing LP Financial Model
A3: Fund Parameters
A5: Initial AUM | C5: 500000000
A6: Management Fee | C6: 50
A7: Performance Fee (% of excess return) | C7: 2000
A8: Hurdle Rate | C8: 400
A9: Other Expenses | C9: 15
A13: Summary Statistics
A14: Return Metrics
A15: Net IRR (Avg Annual Net Yield) | C15: =AVERAGE('Annual Model'!C86,'Annual Model'!D86,'Annual Model'!E86,'Annual Model'!F86,'Annual Model'!G86,'Annual Model'!H86,'Annual Model'!I86,'Annual Model'!J86,'Annual Model'!K86,'Annual Model'!L86,'Annual Model'!M86,'Annual Model'!N86,'Annual Model'!O86,'Annual Model'!P86,'Annual Model'!Q86,'Annual Model'!R86,'Annual Model'!S86,'Annual Model'!T86,'Annual Model'!U86,'Annual Model'!V86)
A16: Gross IRR (Avg Annual Gross Yield) | C16: =AVERAGE('Annual Model'!C33,'Annual Model'!D33,'Annual Model'!E33,'Annual Model'!F33,'Annual Model'!G33,'Annual Model'!H33,'Annual Model'!I33,'Annual Model'!J33,'Annual Model'!K33,'Annual Model'!L33,'Annual Model'!M33,'Annual Model'!N33,'Annual Model'!O33,'Annual Model'!P33,'Annual Model'!Q33,'Annual Model'!R33,'Annual Model'!S33,'Annual Model'!T33,'Annual Model'!U33,'Annual Model'!V33)
A17: MOIC (Multiple on Invested Capital) | C17: ='Annual Model'!V87/Summary!$C$5
A18: DPI (Distributions to Paid-In) | C18: =('Annual Model'!C85+'Annual Model'!D85+'Annual Model'!E85+'Annual Model'!F85+'Annual Model'!G85+'Annual Model'!H85+'Annual Model'!I85+'Annual Model'!J85+'Annual Model'!K85+'Annual Model'!L85+'Annual Model'!M85+'Annual Model'!N85+'Annual Model'!O85+'Annual Model'!P85+'Annual Model'!Q85+'Annual Model'!R85+'Annual Model'!S85+'Annual Model'!T85+'Annual Model'!U85+'Annual Model'!V85)/Summary!$C$5
A19: Total Value to Paid-In (TVPI) | C19: =('Annual Model'!V87+'Annual Model'!C85+'Annual Model'!D85+'Annual Model'!E85+'Annual Model'!F85+'Annual Model'!G85+'Annual Model'!H85+'Annual Model'!I85+'Annual Model'!J85+'Annual Model'!K85+'Annual Model'!L85+'Annual Model'!M85+'Annual Model'!N85+'Annual Model'!O85+'Annual Model'!P85+'Annual Model'!Q85+'Annual Model'!R85+'Annual Model'!S85+'Annual Model'!T85+'Annual Model'!U85+'Annual Model'!V85)/Summary!$C$5
A21: Capital Metrics
A22: Initial Committed Capital | C22: =Summary!$C$5
A23: Ending AUM (Year 20) | C23: ='Annual Model'!V87
A24: Total AUM Growth | C24: ='Annual Model'!V87/Summary!$C$5-1
A25: Total Cumulative Net Income | C25: ='Annual Model'!C85+'Annual Model'!D85+'Annual Model'!E85+'Annual Model'!F85+'Annual Model'!G85+'Annual Model'!H85+'Annual Model'!I85+'Annual Model'!J85+'Annual Model'!K85+'Annual Model'!L85+'Annual Model'!M85+'Annual Model'!N85+'Annual Model'!O85+'Annual Model'!P85+'Annual Model'!Q85+'Annual Model'!R85+'Annual Model'!S85+'Annual Model'!T85+'Annual Model'!U85+'Annual Model'!V85
A26: Total Cumulative Gross Income | C26: ='Annual Model'!C75+'Annual Model'!D75+'Annual Model'!E75+'Annual Model'!F75+'Annual Model'!G75+'Annual Model'!H75+'Annual Model'!I75+'Annual Model'!J75+'Annual Model'!K75+'Annual Model'!L75+'Annual Model'!M75+'Annual Model'!N75+'Annual Model'!O75+'Annual Model'!P75+'Annual Model'!Q75+'Annual Model'!R75+'Annual Model'!S75+'Annual Model'!T75+'Annual Model'!U75+'Annual Model'!V75
A27: Peak AUM | C27: =MAX('Annual Model'!C87,'Annual Model'!D87,'Annual Model'!E87,'Annual Model'!F87,'Annual Model'!G87,'Annual Model'!H87,'Annual Model'!I87,'Annual Model'!J87,'Annual Model'!K87,'Annual Model'!L87,'Annual Model'!M87,'Annual Model'!N87,'Annual Model'!O87,'Annual Model'!P87,'Annual Model'!Q87,'Annual Model'!R87,'Annual Model'!S87,'Annual Model'!T87,'Annual Model'!U87,'Annual Model'!V87)
A29: Fee & Expense Metrics
A30: Total Management Fees | C30: ='Annual Model'!C78+'Annual Model'!D78+'Annual Model'!E78+'Annual Model'!F78+'Annual Model'!G78+'Annual Model'!H78+'Annual Model'!I78+'Annual Model'!J78+'Annual Model'!K78+'Annual Model'!L78+'Annual Model'!M78+'Annual Model'!N78+'Annual Model'!O78+'Annual Model'!P78+'Annual Model'!Q78+'Annual Model'!R78+'Annual Model'!S78+'Annual Model'!T78+'Annual Model'!U78+'Annual Model'!V78
A31: Total Performance Fees | C31: ='Annual Model'!C80+'Annual Model'!D80+'Annual Model'!E80+'Annual Model'!F80+'Annual Model'!G80+'Annual Model'!H80+'Annual Model'!I80+'Annual Model'!J80+'Annual Model'!K80+'Annual Model'!L80+'Annual Model'!M80+'Annual Model'!N80+'Annual Model'!O80+'Annual Model'!P80+'Annual Model'!Q80+'Annual Model'!R80+'Annual Model'!S80+'Annual Model'!T80+'Annual Model'!U80+'Annual Model'!V80
A32: Total Other Expenses | C32: ='Annual Model'!C81+'Annual Model'!D81+'Annual Model'!E81+'Annual Model'!F81+'Annual Model'!G81+'Annual Model'!H81+'Annual Model'!I81+'Annual Model'!J81+'Annual Model'!K81+'Annual Model'!L81+'Annual Model'!M81+'Annual Model'!N81+'Annual Model'!O81+'Annual Model'!P81+'Annual Model'!Q81+'Annual Model'!R81+'Annual Model'!S81+'Annual Model'!T81+'Annual Model'!U81+'Annual Model'!V81
A33: Total All-In Fees & Expenses | C33: ='Annual Model'!C82+'Annual Model'!D82+'Annual Model'!E82+'Annual Model'!F82+'Annual Model'!G82+'Annual Model'!H82+'Annual Model'!I82+'Annual Model'!J82+'Annual Model'!K82+'Annual Model'!L82+'Annual Model'!M82+'Annual Model'!N82+'Annual Model'!O82+'Annual Model'!P82+'Annual Model'!Q82+'Annual Model'!R82+'Annual Model'!S82+'Annual Model'!T82+'Annual Model'!U82+'Annual Model'!V82
A34: Fee Drag (Fees / Gross Income) | C34: =IF(C26=0,0,C33/C26)
A35: Net-to-Gross Ratio | C35: =IF(C26=0,0,C25/C26)
A37: Yield & Risk Metrics
A38: Year 1 Net Yield | C38: ='Annual Model'!C86
A39: Year 20 Net Yield | C39: ='Annual Model'!V86
A40: Best Year Net Yield | C40: =MAX('Annual Model'!C86,'Annual Model'!D86,'Annual Model'!E86,'Annual Model'!F86,'Annual Model'!G86,'Annual Model'!H86,'Annual Model'!I86,'Annual Model'!J86,'Annual Model'!K86,'Annual Model'!L86,'Annual Model'!M86,'Annual Model'!N86,'Annual Model'!O86,'Annual Model'!P86,'Annual Model'!Q86,'Annual Model'!R86,'Annual Model'!S86,'Annual Model'!T86,'Annual Model'!U86,'Annual Model'!V86)
A41: Worst Year Net Yield | C41: =MIN('Annual Model'!C86,'Annual Model'!D86,'Annual Model'!E86,'Annual Model'!F86,'Annual Model'!G86,'Annual Model'!H86,'Annual Model'!I86,'Annual Model'!J86,'Annual Model'!K86,'Annual Model'!L86,'Annual Model'!M86,'Annual Model'!N86,'Annual Model'!O86,'Annual Model'!P86,'Annual Model'!Q86,'Annual Model'!R86,'Annual Model'!S86,'Annual Model'!T86,'Annual Model'!U86,'Annual Model'!V86)
A42: Year 1 Gross Yield | C42: ='Annual Model'!C33
A43: Gross-to-Net Spread (Avg) | C43: =C16-C15
A45: Leverage & Securitization Metrics
A46: Total Leveraged AUM (Year 1) | C46: ='Annual Model'!C45
A47: Leverage Ratio (Year 1) | C47: =IF('Annual Model'!C32=0,0,'Annual Model'!C45/'Annual Model'!C32)
A48: Cumulative Net Leverage Income | C48: ='Annual Model'!C52+'Annual Model'!D52+'Annual Model'!E52+'Annual Model'!F52+'Annual Model'!G52+'Annual Model'!H52+'Annual Model'!I52+'Annual Model'!J52+'Annual Model'!K52+'Annual Model'!L52+'Annual Model'!M52+'Annual Model'!N52+'Annual Model'!O52+'Annual Model'!P52+'Annual Model'!Q52+'Annual Model'!R52+'Annual Model'!S52+'Annual Model'!T52+'Annual Model'!U52+'Annual Model'!V52
A49: Cumulative Net Securitization Income | C49: ='Annual Model'!C73+'Annual Model'!D73+'Annual Model'!E73+'Annual Model'!F73+'Annual Model'!G73+'Annual Model'!H73+'Annual Model'!I73+'Annual Model'!J73+'Annual Model'!K73+'Annual Model'!L73+'Annual Model'!M73+'Annual Model'!N73+'Annual Model'!O73+'Annual Model'!P73+'Annual Model'!Q73+'Annual Model'!R73+'Annual Model'!S73+'Annual Model'!T73+'Annual Model'!U73+'Annual Model'!V73
...

Sheet Market Rates
A1: Market Rate Assumptions (Bloomberg)
A3: BENCHMARK RATES
C4: Year 1 | D4: Year 2 | E4: Year 3 | F4: Year 4 | G4: Year 5 | H4: Year 6 | I4: Year 7 | J4: Year 8 | K4: Year 9 | L4: Year 10 | M4: Year 11 | N4: Year 12 | O4: Year 13 | P4: Year 14 | Q4: Year 15 | R4: Year 16 | S4: Year 17 | T4: Year 18 | U4: Year 19 | V4: Year 20
A5: SOFR (Secured Overnight Financing Rate) | B5: % | C5: 0.043 | D5: 0.0415 | E5: 0.04 | F5: 0.0385 | G5: 0.037 | H5: 0.0355 | I5: 0.0345 | J5: 0.0335 | K5: 0.0325 | L5: 0.032 | M5: 0.0315 | N5: 0.031 | O5: 0.0308 | P5: 0.0305 | Q5: 0.0303 | R5: 0.03 | S5: 0.03 | T5: 0.03 | U5: 0.03 | V5: 0.03
A6: SIFMA (Municipal Swap Index) | B6: % | C6: 0.035 | D6: 0.034 | E6: 0.033 | F6: 0.032 | G6: 0.031 | H6: 0.03 | I6: 0.0293 | J6: 0.0285 | K6: 0.028 | L6: 0.0275 | M6: 0.027 | N6: 0.0268 | O6: 0.0265 | P6: 0.0263 | Q6: 0.026 | R6: 0.0258 | S6: 0.0255 | T6: 0.0253 | U6: 0.025 | V6: 0.025
A8: SPREAD ASSUMPTIONS
A9: Repo Spread over SOFR | B9: bps | C9: 25 | D9: 25 | E9: 25 | F9: 25 | G9: 25 | H9: 25 | I9: 25 | J9: 25 | K9: 25 | L9: 25 | M9: 25 | N9: 25 | O9: 25 | P9: 25 | Q9: 25 | R9: 25 | S9: 25 | T9: 25 | U9: 25 | V9: 25
A10: TOB Spread over SIFMA | B10: bps | C10: 15 | D10: 15 | E10: 15 | F10: 15 | G10: 15 | H10: 15 | I10: 15 | J10: 15 | K10: 15 | L10: 15 | M10: 15 | N10: 15 | O10: 15 | P10: 15 | Q10: 15 | R10: 15 | S10: 15 | T10: 15 | U10: 15 | V10: 15
A12: ALL-IN FINANCING RATES
A13: Repo All-In Rate (SOFR + Spread) | B13: % | C13: =C5+C9/10000 | D13: =D5+D9/10000 | E13: =E5+E9/10000 | F13: =F5+F9/10000 | G13: =G5+G9/10000 | H13: =H5+H9/10000 | I13: =I5+I9/10000 | J13: =J5+J9/10000 | ... V13: =V5+V9/10000
A14: TOB All-In Rate (SIFMA + Spread) | B14: % | C14: =C6+C10/10000 | D14: =D6+D10/10000 | E14: =E6+E10/10000 | F14: =F6+F10/10000 | G14: =G6+G10/10000 | H14: =H6+H10/10000 | I14: =I6+I10/10000 | J14: =J6+J10/10000 | ... V14: =V6+V10/10000
A16: Enter forward rates from Bloomberg Terminal. Use SOFRRATE Index (SOFR) and MUNIPSA Index (SIFMA). | G16: =Input

Sheet Annual Model
A1: Annual Financial Model
A3: INPUTS
C4: Year 1 | D4: Year 2 | E4: Year 3 | F4: Year 4 | G4: Year 5 | H4: Year 6 | I4: Year 7 | J4: Year 8 | K4: Year 9 | L4: Year 10 | M4: Year 11 | N4: Year 12 | O4: Year 13 | P4: Year 14 | Q4: Year 15 | R4: Year 16 | S4: Year 17 | T4: Year 18 | U4: Year 19 | V4: Year 20
A5: Asset Allocation | B5: %
A6: LIHTC Loans | C6: 0.35 | D6: 0.35 | E6: 0.35 | F6: 0.35 | G6: 0.35 | H6: 0.35 | I6: 0.35 | J6: 0.35 | K6: 0.35 | L6: 0.35 | M6: 0.35 | N6: 0.35 | O6: 0.35 | P6: 0.35 | Q6: 0.35 | R6: 0.35 | S6: 0.35 | T6: 0.35 | U6: 0.35 | V6: 0.35
A7: Municipal Bonds | C7: 0.25 | D7: 0.25 | E7: 0.25 | F7: 0.25 | G7: 0.25 | H7: 0.25 | I7: 0.25 | J7: 0.25 | K7: 0.25 | L7: 0.25 | M7: 0.25 | N7: 0.25 | O7: 0.25 | P7: 0.25 | Q7: 0.25 | R7: 0.25 | S7: 0.25 | T7: 0.25 | U7: 0.25 | V7: 0.25
A8: JVs | C8: 0.15 | D8: 0.15 | E8: 0.15 | F8: 0.15 | G8: 0.15 | H8: 0.15 | I8: 0.15 | J8: 0.15 | K8: 0.15 | L8: 0.15 | M8: 0.15 | N8: 0.15 | O8: 0.15 | P8: 0.15 | Q8: 0.15 | R8: 0.15 | S8: 0.15 | T8: 0.15 | U8: 0.15 | V8: 0.15
A9: Securitization Residuals (B-Pieces) | C9: 0.15 | D9: 0.15 | E9: 0.15 | F9: 0.15 | G9: 0.15 | H9: 0.15 | I9: 0.15 | J9: 0.15 | K9: 0.15 | L9: 0.15 | M9: 0.15 | N9: 0.15 | O9: 0.15 | P9: 0.15 | Q9: 0.15 | R9: 0.15 | S9: 0.15 | T9: 0.15 | U9: 0.15 | V9: 0.15
A10: Cash | C10: 0.1 | D10: 0.1 | E10: 0.1 | F10: 0.1 | G10: 0.1 | H10: 0.1 | I10: 0.1 | J10: 0.1 | K10: 0.1 | L10: 0.1 | M10: 0.1 | N10: 0.1 | O10: 0.1 | P10: 0.1 | Q10: 0.1 | R10: 0.1 | S10: 0.1 | T10: 0.1 | U10: 0.1 | V10: 0.1
A11: Total Allocation | C11: =SUM(C6:C10) | D11: =SUM(D6:D10) | E11: =SUM(E6:E10) | F11: =SUM(F6:F10) | G11: =SUM(G6:G10) | H11: =SUM(H6:H10) | I11: =SUM(I6:I10) | J11: =SUM(J6:J10) | ... V11: =SUM(V6:V10)
A12: Expected Yields | B12: %
A13: LIHTC Loans | C13: 0.065 | D13: 0.065 | E13: 0.065 | F13: 0.065 | G13: 0.065 | H13: 0.065 | I13: 0.065 | J13: 0.065 | K13: 0.065 | L13: 0.065 | M13: 0.065 | N13: 0.065 | O13: 0.065 | P13: 0.065 | Q13: 0.065 | R13: 0.065 | S13: 0.065 | T13: 0.065 | U13: 0.065 | V13: 0.065
A14: Municipal Bonds | C14: 0.045 | D14: 0.045 | E14: 0.045 | F14: 0.045 | G14: 0.045 | H14: 0.045 | I14: 0.045 | J14: 0.045 | K14: 0.045 | L14: 0.045 | M14: 0.045 | N14: 0.045 | O14: 0.045 | P14: 0.045 | Q14: 0.045 | R14: 0.045 | S14: 0.045 | T14: 0.045 | U14: 0.045 | V14: 0.045
A15: JVs | C15: 0.08 | D15: 0.08 | E15: 0.08 | F15: 0.08 | G15: 0.08 | H15: 0.08 | I15: 0.08 | J15: 0.08 | K15: 0.08 | L15: 0.08 | M15: 0.08 | N15: 0.08 | O15: 0.08 | P15: 0.08 | Q15: 0.08 | R15: 0.08 | S15: 0.08 | T15: 0.08 | U15: 0.08 | V15: 0.08
A16: Securitization Residuals (B-Pieces) | C16: 0.075 | D16: 0.075 | E16: 0.075 | F16: 0.075 | G16: 0.075 | H16: 0.075 | I16: 0.075 | J16: 0.075 | K16: 0.075 | L16: 0.075 | M16: 0.075 | N16: 0.075 | O16: 0.075 | P16: 0.075 | Q16: 0.075 | R16: 0.075 | S16: 0.075 | T16: 0.075 | U16: 0.075 | V16: 0.075
A17: Cash | C17: 0.02 | D17: 0.02 | E17: 0.02 | F17: 0.02 | G17: 0.02 | H17: 0.02 | I17: 0.02 | J17: 0.02 | K17: 0.02 | L17: 0.02 | M17: 0.02 | N17: 0.02 | O17: 0.02 | P17: 0.02 | Q17: 0.02 | R17: 0.02 | S17: 0.02 | T17: 0.02 | U17: 0.02 | V17: 0.02
A19: Leverage Parameters (LIHTC Loans Only) | B19: %
A20: Leverage % of LIHTC Loans | C20: 0.25 | D20: 0.25 | E20: 0.25 | F20: 0.25 | G20: 0.25 | H20: 0.25 | I20: 0.25 | J20: 0.25 | K20: 0.25 | L20: 0.25 | M20: 0.25 | N20: 0.25 | O20: 0.25 | P20: 0.25 | Q20: 0.25 | R20: 0.25 | S20: 0.25 | T20: 0.25 | U20: 0.25 | V20: 0.25
A21: Repo Financing Weight (vs TOB) | C21: 0.6 | D21: 0.6 | E21: 0.6 | F21: 0.6 | G21: 0.6 | H21: 0.6 | I21: 0.6 | J21: 0.6 | K21: 0.6 | L21: 0.6 | M21: 0.6 | N21: 0.6 | O21: 0.6 | P21: 0.6 | Q21: 0.6 | R21: 0.6 | S21: 0.6 | T21: 0.6 | U21: 0.6 | V21: 0.6
A23: Securitization Parameters
A24: % of Loans to Securitize | C24: 0 | D24: 0 | E24: 0 | F24: 0 | G24: 0 | H24: 0 | I24: 0 | J24: 0 | K24: 0 | L24: 0 | M24: 0 | N24: 0 | O24: 0 | P24: 0 | Q24: 0 | R24: 0 | S24: 0 | T24: 0 | U24: 0 | V24: 0
A25: Loan Advance Rate | C25: 0.85 | D25: 0.85 | E25: 0.85 | F25: 0.85 | G25: 0.85 | H25: 0.85 | I25: 0.85 | J25: 0.85 | K25: 0.85 | L25: 0.85 | M25: 0.85 | N25: 0.85 | O25: 0.85 | P25: 0.85 | Q25: 0.85 | R25: 0.85 | S25: 0.85 | T25: 0.85 | U25: 0.85 | V25: 0.85
A26: Loan Securitization Spread | B26: bps | C26: 150 | D26: 150 | E26: 150 | F26: 150 | G26: 150 | H26: 150 | I26: 150 | J26: 150 | K26: 150 | L26: 150 | M26: 150 | N26: 150 | O26: 150 | P26: 150 | Q26: 150 | R26: 150 | S26: 150 | T26: 150 | U26: 150 | V26: 150
A27: % of JVs to Resecuritize | C27: 0 | D27: 0 | E27: 0 | F27: 0 | G27: 0 | H27: 0 | I27: 0 | J27: 0 | K27: 0 | L27: 0 | M27: 0 | N27: 0 | O27: 0 | P27: 0 | Q27: 0 | R27: 0 | S27: 0 | T27: 0 | U27: 0 | V27: 0
A28: JV Advance Rate | C28: 0.75 | D28: 0.75 | E28: 0.75 | F28: 0.75 | G28: 0.75 | H28: 0.75 | I28: 0.75 | J28: 0.75 | K28: 0.75 | L28: 0.75 | M28: 0.75 | N28: 0.75 | O28: 0.75 | P28: 0.75 | Q28: 0.75 | R28: 0.75 | S28: 0.75 | T28: 0.75 | U28: 0.75 | V28: 0.75
A29: JV Resecuritization Spread | B29: bps | C29: 200 | D29: 200 | E29: 200 | F29: 200 | G29: 200 | H29: 200 | I29: 200 | J29: 200 | K29: 200 | L29: 200 | M29: 200 | N29: 200 | O29: 200 | P29: 200 | Q29: 200 | R29: 200 | S29: 200 | T29: 200 | U29: 200 | V29: 200
A31: PORTFOLIO PERFORMANCE
A32: Beginning AUM | B32: $ | C32: =Summary!$C$5 | D32: =C87 | E32: =D87 | F32: =E87 | G32: =F87 | H32: =G87 | I32: =H87 | J32: =I87 | K32: =J87 | ... V32: =U87
A33: Gross Portfolio Yield | B33: % | C33: =SUMPRODUCT(C6:C10,C13:C17) | D33: =SUMPRODUCT(D6:D10,D13:D17) | E33: =SUMPRODUCT(E6:E10,E13:E17) | F33: =SUMPRODUCT(F6:F10,F13:F17) | G33: =SUMPRODUCT(G6:G10,G13:G17) | H33: =SUMPRODUCT(H6:H10,H13:H17) | I33: =SUMPRODUCT(I6:I10,I13:I17) | J33: =SUMPRODUCT(J6:J10,J13:J17) | ... V33: =SUMPRODUCT(V6:V10,V13:V17)
A35: Income by Asset Class | B35: $
A36: LIHTC Loans | C36: =C32*C6*C13 | D36: =D32*D6*D13 | E36: =E32*E6*E13 | F36: =F32*F6*F13 | G36: =G32*G6*G13 | H36: =H32*H6*H13 | I36: =I32*I6*I13 | J36: =J32*J6*J13 | ... V36: =V32*V6*V13
A37: Municipal Bonds | C37: =C32*C7*C14 | D37: =D32*D7*D14 | E37: =E32*E7*E14 | F37: =F32*F7*F14 | G37: =G32*G7*G14 | H37: =H32*H7*H14 | I37: =I32*I7*I14 | J37: =J32*J7*J14 | ... V37: =V32*V7*V14
A38: JVs | C38: =C32*C8*C15 | D38: =D32*D8*D15 | E38: =E32*E8*E15 | F38: =F32*F8*F15 | G38: =G32*G8*G15 | H38: =H32*H8*H15 | I38: =I32*I8*I15 | J38: =J32*J8*J15 | ... V38: =V32*V8*V15
A39: Securitization Residuals (B-Pieces) | C39: =C32*C9*C16 | D39: =D32*D9*D16 | E39: =E32*E9*E16 | F39: =F32*F9*F16 | G39: =G32*G9*G16 | H39: =H32*H9*H16 | I39: =I32*I9*I16 | J39: =J32*J9*J16 | ... V39: =V32*V9*V16
A40: Cash | C40: =C32*C10*C17 | D40: =D32*D10*D17 | E40: =E32*E10*E17 | F40: =F32*F10*F17 | G40: =G32*G10*G17 | H40: =H32*H10*H17 | I40: =I32*I10*I17 | J40: =J32*J10*J17 | ... V40: =V32*V10*V17
A41: Total Asset Income | C41: =SUM(C36:C40) | D41: =SUM(D36:D40) | E41: =SUM(E36:E40) | F41: =SUM(F36:F40) | G41: =SUM(G36:G40) | H41: =SUM(H36:H40) | I41: =SUM(I36:I40) | J41: =SUM(J36:J40) | ... V41: =SUM(V36:V40)
A43: LEVERAGE (LIHTC LOANS ONLY)
A44: LIHTC Loan AUM | B44: $ | C44: =C32*C6 | D44: =D32*D6 | E44: =E32*E6 | F44: =F32*F6 | G44: =G32*G6 | H44: =H32*H6 | I44: =I32*I6 | J44: =J32*J6 | ... V44: =V32*V6
A45: Leveraged Amount | C45: =C44*C20 | D45: =D44*D20 | E45: =E44*E20 | F45: =F44*F20 | G45: =G44*G20 | H45: =H44*H20 | I45: =I44*I20 | J45: =J44*J20 | ... V45: =V44*V20
A46: Repo Portion | C46: =C45*C21 | D46: =D45*D21 | E46: =E45*E21 | F46: =F45*F21 | G46: =G45*G21 | H46: =H45*H21 | I46: =I45*I21 | J46: =J45*J21 | ... V46: =V45*V21
...
